<?xml version="1.0" ?>
<mujoco model="right_arm_leader">
  <compiler angle="radian" meshdir="assets" autolimits="true"/>
  <default>
    <default class="right_arm_leader">
      <joint frictionloss="0.1" armature="0.005"/>
      <position kp="50" dampratio="1"/>
      <default class="visual">
        <geom type="mesh" contype="0" conaffinity="0" group="2"/>
      </default>
      <default class="collision">
        <geom group="3"/>
      </default>
    </default>
  </default>
  <worldbody>
    <body name="shoulder_pitch_link" pos="0 0 0" quat="1 0 0 0" childclass="right_arm_leader">
      <freejoint name="shoulder_pitch_link_freejoint"/>
      <inertial pos="-5.8682e-19 -0.0126181 -0.00340591" mass="0.015" fullinertia="3.15515e-06 6.46393e-06 7.18717e-06 6.06171e-22 -2.1187e-21 -6.81062e-07"/>
      <geom type="mesh" class="visual" pos="-5.8682e-19 -0.0126181 -0.00340591" quat="1 0 0 0" mesh="shoulder_pitch_link_visual" material="shoulder_pitch_link_visual_material"/>
      <geom type="mesh" class="collision" pos="-5.8682e-19 -0.0126181 -0.00340591" quat="1 0 0 0" mesh="shoulder_pitch_link_collision" material="shoulder_pitch_link_collision_material"/>
      <body name="shoulder_roll_link" pos="0.019 -0.027 -0.0107595" quat="0.5 -0.5 -0.5 0.5">
        <joint axis="0 0 1" name="shoulder_roll" type="hinge" range="-0.4363323129985824 1.5707963267948966"/>
        <inertial pos="-0.0117742 0.00203621 0.0185402" mass="0.1152" fullinertia="2.66048e-05 3.22106e-05 3.47015e-05 -5.23536e-07 3.29512e-08 -6.36618e-07"/>
        <geom type="mesh" class="visual" pos="-0.0117742 0.00203621 0.0185402" quat="0.5 0.5 0.5 -0.5" mesh="shoulder_roll_link_visual" material="shoulder_roll_link_visual_material"/>
        <geom type="mesh" class="collision" pos="-0.0117742 0.00203621 0.0185402" quat="0.5 0.5 0.5 -0.5" mesh="shoulder_roll_link_collision" material="shoulder_roll_link_collision_material"/>
        <body name="shoulder_gear_drive" pos="-0.024 0.019 0.019" quat="0.5 0.5 -0.5 0.5">
          <joint axis="0 0 1" name="shoulder_yaw_drive" type="hinge" range="-3.141592653589793 3.141592653589793"/>
          <inertial pos="2.34905e-15 1.15819e-15 -0.00662386" mass="0.004" fullinertia="1.9527e-07 1.9527e-07 2.87762e-07 -2.80555e-15 2.40741e-35 -6.01853e-36"/>
          <geom type="mesh" class="visual" pos="2.34905e-15 1.1588e-15 -0.00662386" quat="4.60865e-14 -3.48413e-13 -7.13873e-14 -1" mesh="shoulder_gear_drive_visual" material="shoulder_gear_drive_visual_material"/>
          <geom type="mesh" class="collision" pos="2.34905e-15 1.1588e-15 -0.00662386" quat="4.60865e-14 -3.48413e-13 -7.13873e-14 -1" mesh="shoulder_gear_drive_collision" material="shoulder_gear_drive_collision_material"/>
        </body>
        <body name="shoulder_yaw_link" pos="-3.58106e-10 0.025 0.019" quat="0.5 -0.5 -0.5 -0.5">
          <joint axis="0 0 1" name="shoulder_yaw_driven" type="hinge" range="-3.141592653589793 3.141592653589793"/>
          <inertial pos="-3.81081e-18 -1.36694e-16 0.0282698" mass="0.0247439" fullinertia="9.99474e-06 1.34615e-05 5.23493e-06 -4.50573e-13 3.26327e-22 -8.4756e-20"/>
          <geom type="mesh" class="visual" pos="-3.96629e-18 -1.38778e-16 0.0282698" quat="2.07134e-13 2.78262e-14 1 -3.6991e-13" mesh="shoulder_yaw_link_visual" material="shoulder_yaw_link_visual_material"/>
          <geom type="mesh" class="collision" pos="-3.96629e-18 -1.38778e-16 0.0282698" quat="2.07134e-13 2.78262e-14 1 -3.6991e-13" mesh="shoulder_yaw_link_collision" material="shoulder_yaw_link_collision_material"/>
          <body name="elbow_roll_link" pos="-0.019 -6.245e-17 0.061" quat="0.5 -0.5 0.5 -0.5">
            <joint axis="0 0 1" name="elbow_roll" type="hinge" range="-2.268928027592625 3.552713678800501e-15"/>
            <inertial pos="0.0117742 -0.00203621 0.0185402" mass="0.1152" fullinertia="2.66048e-05 3.22106e-05 3.47015e-05 -5.23536e-07 -3.29512e-08 6.36618e-07"/>
            <geom type="mesh" class="visual" pos="0.0117742 -0.00203621 0.0185402" quat="0.5 -0.5 0.5 0.5" mesh="elbow_roll_link_visual" material="elbow_roll_link_visual_material"/>
            <geom type="mesh" class="collision" pos="0.0117742 -0.00203621 0.0185402" quat="0.5 -0.5 0.5 0.5" mesh="elbow_roll_link_collision" material="elbow_roll_link_collision_material"/>
            <body name="elbow_gear_drive" pos="0.024 -0.019 0.019" quat="0.5 -0.5 0.5 0.5">
              <joint axis="0 0 1" name="elbow_yaw_drive" type="hinge" range="-3.1415926535897913 3.141592653589795"/>
              <inertial pos="2.34898e-15 1.16595e-15 -0.00662386" mass="0.004" fullinertia="1.9527e-07 1.9527e-07 2.87762e-07 -2.80555e-15 1.20371e-35 2.40741e-35"/>
              <geom type="mesh" class="visual" pos="2.34898e-15 1.16573e-15 -0.00662386" quat="1 2.41985e-13 -2.23821e-13 7.68628e-14" mesh="elbow_gear_drive_visual" material="elbow_gear_drive_visual_material"/>
              <geom type="mesh" class="collision" pos="2.34898e-15 1.16573e-15 -0.00662386" quat="1 2.41985e-13 -2.23821e-13 7.68628e-14" mesh="elbow_gear_drive_collision" material="elbow_gear_drive_collision_material"/>
            </body>
            <body name="elbow_yaw_link" pos="3.58092e-10 -0.025 0.019" quat="0.5 0.5 -0.5 0.5">
              <joint axis="0 0 1" name="elbow_yaw_driven" type="hinge" range="-3.141592653589795 3.1415926535897913"/>
              <inertial pos="-1.48734e-11 -0.00632991 0.0336872" mass="0.0295299" fullinertia="2.87888e-05 1.67326e-05 1.41008e-05 2.23812e-13 9.4146e-16 3.99712e-06"/>
              <geom type="mesh" class="visual" pos="-1.48734e-11 -0.00632991 0.0336872" quat="5.41387e-14 2.88572e-14 1 -4.40333e-13" mesh="elbow_yaw_link_visual" material="elbow_yaw_link_visual_material"/>
              <geom type="mesh" class="collision" pos="-1.48734e-11 -0.00632991 0.0336872" quat="5.41387e-14 2.88572e-14 1 -4.40333e-13" mesh="elbow_yaw_link_collision" material="elbow_yaw_link_collision_material"/>
              <body name="wrist_pitch_link" pos="-9.49737e-18 -0.022 0.061" quat="0.5 -0.5 -0.5 -0.5">
                <joint axis="0 0 1" name="wrist_pitch_driven" type="hinge" range="-2.0943951023931953 2.0943951023931953"/>
                <inertial pos="-0.011508 -0.000415054 0.0218673" mass="0.1276" fullinertia="3.30134e-05 4.15977e-05 3.57593e-05 1.9227e-08 -1.97148e-07 5.35788e-07"/>
                <geom type="mesh" class="visual" pos="-0.011508 -0.000415054 0.0218673" quat="0.5 0.5 -0.5 -0.5" mesh="wrist_pitch_link_visual" material="wrist_pitch_link_visual_material"/>
                <geom type="mesh" class="collision" pos="-0.011508 -0.000415054 0.0218673" quat="0.5 0.5 -0.5 -0.5" mesh="wrist_pitch_link_collision" material="wrist_pitch_link_collision_material"/>
                <body name="wrist_gear_drive" pos="-0.024 1.52469e-10 0.003" quat="4.90348e-13 -0.707107 0.707107 4.20862e-14">
                  <joint axis="0 0 1" name="wrist_pitch_drive" type="hinge" range="-2.0943951023931953 2.0943951023931953"/>
                  <inertial pos="2.93824e-15 -1.09267e-16 0.00503438" mass="0.003" fullinertia="1.33264e-07 1.33264e-07 2.24433e-07 1.59295e-15 1.48407e-35 7.05737e-36"/>
                  <geom type="mesh" class="visual" pos="2.93824e-15 -1.11022e-16 0.00503438" quat="0.707107 -0.707107 9.59233e-14 4.75334e-13" mesh="wrist_gear_drive_visual" material="wrist_gear_drive_visual_material"/>
                  <geom type="mesh" class="collision" pos="2.93824e-15 -1.11022e-16 0.00503438" quat="0.707107 -0.707107 9.59233e-14 4.75334e-13" mesh="wrist_gear_drive_collision" material="wrist_gear_drive_collision_material"/>
                </body>
                <body name="leader_hand" pos="3.58074e-10 -0.019 0.022" quat="0.5 0.5 -0.5 0.5">
                  <joint axis="0 0 1" name="wrist_roll" type="hinge" range="-1.5707963267941452 1.570796326795648"/>
                  <inertial pos="2.41105e-08 -0.0406582 -0.0193391" mass="0.017" fullinertia="9.19142e-06 6.63273e-06 3.79456e-06 -1.39884e-12 9.47511e-12 4.48222e-08"/>
                  <geom type="mesh" class="visual" pos="2.41105e-08 -0.0406582 -0.0193391" quat="0.5 -0.5 -0.5 -0.5" mesh="leader_hand_visual" material="leader_hand_visual_material"/>
                  <geom type="mesh" class="collision" pos="2.41105e-08 -0.0406582 -0.0193391" quat="0.5 -0.5 -0.5 -0.5" mesh="leader_hand_collision" material="leader_hand_collision_material"/>
                </body>
              </body>
            </body>
          </body>
        </body>
      </body>
    </body>
  </worldbody>
  <asset>
    <mesh file="merged/elbow_roll_link_collision.stl"/>
    <mesh file="merged/elbow_gear_drive_visual.stl"/>
    <mesh file="merged/shoulder_pitch_link_collision.stl"/>
    <mesh file="merged/wrist_gear_drive_collision.stl"/>
    <mesh file="merged/elbow_yaw_link_visual.stl"/>
    <mesh file="merged/shoulder_roll_link_collision.stl"/>
    <mesh file="merged/wrist_pitch_link_collision.stl"/>
    <mesh file="merged/elbow_yaw_link_collision.stl"/>
    <mesh file="merged/wrist_gear_drive_visual.stl"/>
    <mesh file="merged/shoulder_yaw_link_visual.stl"/>
    <mesh file="merged/shoulder_roll_link_visual.stl"/>
    <mesh file="merged/shoulder_gear_drive_visual.stl"/>
    <mesh file="merged/shoulder_yaw_link_collision.stl"/>
    <mesh file="merged/elbow_roll_link_visual.stl"/>
    <mesh file="merged/leader_hand_collision.stl"/>
    <mesh file="merged/elbow_gear_drive_collision.stl"/>
    <mesh file="merged/wrist_pitch_link_visual.stl"/>
    <mesh file="merged/shoulder_gear_drive_collision.stl"/>
    <mesh file="merged/shoulder_pitch_link_visual.stl"/>
    <mesh file="merged/leader_hand_visual.stl"/>
    <material name="shoulder_pitch_link_visual_material" rgba="0.615686 0.811765 0.929412 1"/>
    <material name="shoulder_pitch_link_collision_material" rgba="0.615686 0.811765 0.929412 1"/>
    <material name="shoulder_roll_link_visual_material" rgba="0.75922 0.862174 0.917756 1"/>
    <material name="shoulder_roll_link_collision_material" rgba="0.75922 0.862174 0.917756 1"/>
    <material name="shoulder_gear_drive_visual_material" rgba="0.615686 0.811765 0.929412 1"/>
    <material name="shoulder_gear_drive_collision_material" rgba="0.615686 0.811765 0.929412 1"/>
    <material name="shoulder_yaw_link_visual_material" rgba="0.542005 0.729062 0.886557 1"/>
    <material name="shoulder_yaw_link_collision_material" rgba="0.542005 0.729062 0.886557 1"/>
    <material name="elbow_roll_link_visual_material" rgba="0.75922 0.862174 0.917756 1"/>
    <material name="elbow_roll_link_collision_material" rgba="0.75922 0.862174 0.917756 1"/>
    <material name="elbow_gear_drive_visual_material" rgba="0.615686 0.811765 0.929412 1"/>
    <material name="elbow_gear_drive_collision_material" rgba="0.615686 0.811765 0.929412 1"/>
    <material name="elbow_yaw_link_visual_material" rgba="0.516885 0.653641 0.793594 1"/>
    <material name="elbow_yaw_link_collision_material" rgba="0.516885 0.653641 0.793594 1"/>
    <material name="wrist_pitch_link_visual_material" rgba="0.748702 0.84202 0.892409 1"/>
    <material name="wrist_pitch_link_collision_material" rgba="0.748702 0.84202 0.892409 1"/>
    <material name="wrist_gear_drive_visual_material" rgba="0.615686 0.811765 0.929412 1"/>
    <material name="wrist_gear_drive_collision_material" rgba="0.615686 0.811765 0.929412 1"/>
    <material name="leader_hand_visual_material" rgba="0.615686 0.811765 0.929412 1"/>
    <material name="leader_hand_collision_material" rgba="0.615686 0.811765 0.929412 1"/>
  </asset>
  <actuator>
    <position class="right_arm_leader" name="shoulder_roll" joint="shoulder_roll" inheritrange="1"/>
    <position class="right_arm_leader" name="shoulder_yaw_drive" joint="shoulder_yaw_drive" inheritrange="1"/>
    <position class="right_arm_leader" name="elbow_roll" joint="elbow_roll" inheritrange="1"/>
    <position class="right_arm_leader" name="elbow_yaw_drive" joint="elbow_yaw_drive" inheritrange="1"/>
    <position class="right_arm_leader" name="wrist_pitch_drive" joint="wrist_pitch_drive" inheritrange="1"/>
    <position class="right_arm_leader" name="wrist_roll" joint="wrist_roll" inheritrange="1"/>
  </actuator>
  <equality>
    <joint joint1="shoulder_yaw_driven" joint2="shoulder_yaw_drive" polycoef="0 -1.0 0 0 0"/>
    <joint joint1="elbow_yaw_driven" joint2="elbow_yaw_drive" polycoef="0 -1.0 0 0 0"/>
    <joint joint1="wrist_pitch_driven" joint2="wrist_pitch_drive" polycoef="0 -1.0 0 0 0"/>
  </equality>
</mujoco>