<?xml version="1.0" ?>
<mujoco model="left_arm_gripper">
  <compiler angle="radian" meshdir="assets" autolimits="true"/>
  <default>
    <default class="left_arm_gripper">
      <joint frictionloss="0.1" armature="0.005"/>
      <position kp="50" dampratio="1"/>
      <default class="visual">
        <geom type="mesh" contype="0" conaffinity="0" group="2"/>
      </default>
      <default class="collision">
        <geom group="3"/>
      </default>
    </default>
  </default>
  <worldbody>
    <body name="shoulder_pitch_link" pos="0 0 0" quat="1 0 0 0" childclass="left_arm_gripper">
      <freejoint name="shoulder_pitch_link_freejoint"/>
      <inertial pos="3.01532e-19 0.0126181 -0.00340591" mass="0.015" fullinertia="3.15515e-06 6.46393e-06 7.18717e-06 4.79639e-22 2.48946e-21 6.81062e-07"/>
      <geom type="mesh" class="visual" pos="3.01532e-19 0.0126181 -0.00340591" quat="1 0 0 0" mesh="shoulder_pitch_link_visual" material="shoulder_pitch_link_visual_material"/>
      <geom type="mesh" class="collision" pos="3.01532e-19 0.0126181 -0.00340591" quat="1 0 0 0" mesh="shoulder_pitch_link_collision" material="shoulder_pitch_link_collision_material"/>
      <body name="shoulder_roll_link" pos="-0.019 0.027 -0.0107595" quat="0.5 -0.5 0.5 -0.5">
        <joint axis="0 0 1" name="shoulder_roll" type="hinge" range="-0.4363323129985806 1.5707963267948983"/>
        <inertial pos="-0.0117742 0.00203621 0.0185402" mass="0.1152" fullinertia="2.66048e-05 3.22106e-05 3.47015e-05 -5.23536e-07 3.29512e-08 -6.36618e-07"/>
        <geom type="mesh" class="visual" pos="-0.0117742 0.00203621 0.0185402" quat="0.5 0.5 -0.5 0.5" mesh="shoulder_roll_link_visual" material="shoulder_roll_link_visual_material"/>
        <geom type="mesh" class="collision" pos="-0.0117742 0.00203621 0.0185402" quat="0.5 0.5 -0.5 0.5" mesh="shoulder_roll_link_collision" material="shoulder_roll_link_collision_material"/>
        <body name="shoulder_gear_drive" pos="-0.024 0.019 0.019" quat="0.5 0.5 -0.5 0.5">
          <joint axis="0 0 1" name="shoulder_yaw_drive" type="hinge" range="-3.141592653589793 3.141592653589793"/>
          <inertial pos="2.34896e-15 1.1542e-15 -0.00662386" mass="0.004" fullinertia="1.9527e-07 1.9527e-07 2.87762e-07 -2.80555e-15 -4.59487e-35 -1.22608e-35"/>
          <geom type="mesh" class="visual" pos="2.34896e-15 1.1588e-15 -0.00662386" quat="1 -7.15816e-14 3.78364e-13 4.62068e-14" mesh="shoulder_gear_drive_visual" material="shoulder_gear_drive_visual_material"/>
          <geom type="mesh" class="collision" pos="2.34896e-15 1.1588e-15 -0.00662386" quat="1 -7.15816e-14 3.78364e-13 4.62068e-14" mesh="shoulder_gear_drive_collision" material="shoulder_gear_drive_collision_material"/>
        </body>
        <body name="shoulder_yaw_link" pos="-3.58105e-10 0.025 0.019" quat="0.5 -0.5 -0.5 -0.5">
          <joint axis="0 0 1" name="shoulder_yaw_driven" type="hinge" range="-3.141592653589793 3.141592653589793"/>
          <inertial pos="-2.78576e-18 -1.40033e-16 0.0282698" mass="0.0247439" fullinertia="9.99474e-06 1.34615e-05 5.23493e-06 -4.50573e-13 4.71821e-23 -8.48439e-20"/>
          <geom type="mesh" class="visual" pos="-2.78263e-18 -1.42247e-16 0.0282698" quat="3.70541e-13 1 -2.79851e-14 2.36971e-13" mesh="shoulder_yaw_link_visual" material="shoulder_yaw_link_visual_material"/>
          <geom type="mesh" class="collision" pos="-2.78263e-18 -1.42247e-16 0.0282698" quat="3.70541e-13 1 -2.79851e-14 2.36971e-13" mesh="shoulder_yaw_link_collision" material="shoulder_yaw_link_collision_material"/>
          <body name="elbow_roll_link" pos="-0.019 -1.2837e-15 0.061" quat="0.5 -0.5 0.5 -0.5">
            <joint axis="0 0 1" name="elbow_roll" type="hinge" range="-2.2689280275926285 0.0"/>
            <inertial pos="0.0117742 -0.00203621 0.0185402" mass="0.1152" fullinertia="2.66048e-05 3.22106e-05 3.47015e-05 -5.23536e-07 -3.29512e-08 6.36618e-07"/>
            <geom type="mesh" class="visual" pos="0.0117742 -0.00203621 0.0185402" quat="0.5 -0.5 -0.5 -0.5" mesh="elbow_roll_link_visual" material="elbow_roll_link_visual_material"/>
            <geom type="mesh" class="collision" pos="0.0117742 -0.00203621 0.0185402" quat="0.5 -0.5 -0.5 -0.5" mesh="elbow_roll_link_collision" material="elbow_roll_link_collision_material"/>
            <body name="elbow_gear_drive" pos="0.024 -0.019 0.019" quat="0.5 -0.5 0.5 0.5">
              <joint axis="0 0 1" name="elbow_yaw_drive" type="hinge" range="-3.1415926535897922 3.141592653589794"/>
              <inertial pos="2.34896e-15 1.16324e-15 -0.00662386" mass="0.004" fullinertia="1.9527e-07 1.9527e-07 2.87762e-07 -2.80555e-15 -1.95848e-35 -3.97456e-35"/>
              <geom type="mesh" class="visual" pos="2.34896e-15 1.16573e-15 -0.00662386" quat="7.35922e-14 2.54239e-13 2.43139e-13 -1" mesh="elbow_gear_drive_visual" material="elbow_gear_drive_visual_material"/>
              <geom type="mesh" class="collision" pos="2.34896e-15 1.16573e-15 -0.00662386" quat="7.35922e-14 2.54239e-13 2.43139e-13 -1" mesh="elbow_gear_drive_collision" material="elbow_gear_drive_collision_material"/>
            </body>
            <body name="elbow_yaw_link" pos="3.58093e-10 -0.025 0.019" quat="0.5 0.5 -0.5 0.5">
              <joint axis="0 0 1" name="elbow_yaw_driven" type="hinge" range="-3.141592653589794 3.1415926535897922"/>
              <inertial pos="-1.48734e-11 -0.00632991 0.0336872" mass="0.0295299" fullinertia="2.87888e-05 1.67326e-05 1.41008e-05 2.23812e-13 9.41459e-16 3.99712e-06"/>
              <geom type="mesh" class="visual" pos="-1.48734e-11 -0.00632991 0.0336872" quat="4.4117e-13 1 -2.79545e-14 8.3864e-14" mesh="elbow_yaw_link_visual" material="elbow_yaw_link_visual_material"/>
              <geom type="mesh" class="collision" pos="-1.48734e-11 -0.00632991 0.0336872" quat="4.4117e-13 1 -2.79545e-14 8.3864e-14" mesh="elbow_yaw_link_collision" material="elbow_yaw_link_collision_material"/>
              <body name="wrist_pitch_link" pos="-5.2897e-18 -0.022 0.061" quat="0.5 -0.5 -0.5 -0.5">
                <joint axis="0 0 1" name="wrist_pitch_driven" type="hinge" range="-2.0943951023931953 2.0943951023931953"/>
                <inertial pos="-0.011508 -0.000415054 0.0218673" mass="0.1276" fullinertia="3.30134e-05 4.15977e-05 3.57593e-05 1.9227e-08 -1.97148e-07 5.35788e-07"/>
                <geom type="mesh" class="visual" pos="-0.011508 -0.000415054 0.0218673" quat="0.5 -0.5 -0.5 0.5" mesh="wrist_pitch_link_visual" material="wrist_pitch_link_visual_material"/>
                <geom type="mesh" class="collision" pos="-0.011508 -0.000415054 0.0218673" quat="0.5 -0.5 -0.5 0.5" mesh="wrist_pitch_link_collision" material="wrist_pitch_link_collision_material"/>
                <body name="wrist_gear_drive" pos="-0.024 1.52468e-10 0.003" quat="4.97842e-13 -0.707107 0.707107 3.41604e-14">
                  <joint axis="0 0 1" name="wrist_pitch_drive" type="hinge" range="-2.0943951023931953 2.0943951023931953"/>
                  <inertial pos="2.93778e-15 -1.07867e-16 0.00503438" mass="0.003" fullinertia="1.33264e-07 1.33264e-07 2.24433e-07 1.59295e-15 -6.6471e-36 1.27706e-36"/>
                  <geom type="mesh" class="visual" pos="2.93778e-15 -1.11022e-16 0.00503438" quat="4.97318e-13 -7.39542e-14 -0.707107 -0.707107" mesh="wrist_gear_drive_visual" material="wrist_gear_drive_visual_material"/>
                  <geom type="mesh" class="collision" pos="2.93778e-15 -1.11022e-16 0.00503438" quat="4.97318e-13 -7.39542e-14 -0.707107 -0.707107" mesh="wrist_gear_drive_collision" material="wrist_gear_drive_collision_material"/>
                </body>
                <body name="gripper_link" pos="3.58074e-10 -0.019 0.022" quat="0.5 0.5 -0.5 0.5">
                  <joint axis="0 0 1" name="wrist_roll" type="hinge" range="-1.570796326794194 1.570796326795599"/>
                  <inertial pos="-0.00417508 -0.0293532 0.00131407" mass="0.0607365" fullinertia="3.08057e-05 3.12267e-05 1.57463e-05 1.11874e-06 3.20681e-06 -3.17205e-06"/>
                  <geom type="mesh" class="visual" pos="-0.00417508 -0.0293532 0.00131407" quat="0.5 -0.5 0.5 0.5" mesh="gripper_link_visual" material="gripper_link_visual_material"/>
                  <geom type="mesh" class="collision" pos="-0.00417508 -0.0293532 0.00131407" quat="0.5 -0.5 0.5 0.5" mesh="gripper_link_collision" material="gripper_link_collision_material"/>
                  <body name="gripper_gear_drive" pos="-0.0001 -0.0397 0.01195" quat="0.5 -0.5 -0.5 -0.5">
                    <joint axis="0 0 1" name="gripper_rack" type="hinge" range="0.0 2.1642082724729685"/>
                    <inertial pos="-3.81639e-17 3.45298e-17 -0.0025" mass="0.00107037" fullinertia="2.73249e-08 2.73249e-08 5.01899e-08 -3.81338e-37 4.19179e-36 1.32868e-36"/>
                    <geom type="mesh" class="visual" pos="-3.1225e-17 3.1225e-17 -0.0025" quat="7.43743e-14 1.50539e-13 7.69385e-14 -1" mesh="gripper_gear_drive_visual" material="gripper_gear_drive_visual_material"/>
                    <geom type="mesh" class="collision" pos="-3.1225e-17 3.1225e-17 -0.0025" quat="7.43743e-14 1.50539e-13 7.69385e-14 -1" mesh="gripper_gear_drive_collision" material="gripper_gear_drive_collision_material"/>
                  </body>
                  <body name="gripper_finger" pos="0.015975 -0.03985 0.026" quat="7.88714e-16 -7.6292e-17 -1 -1.18079e-15">
                    <joint axis="0 0 1" name="gripper_pinion" type="slide" range="-0.0008730000000100752 0.025999999999989927"/>
                    <inertial pos="0.0160674 -0.0318042 0.0063483" mass="0.0171349" fullinertia="5.69429e-06 3.48204e-06 8.04558e-06 4.15596e-08 2.76812e-08 -5.7747e-07"/>
                    <geom type="mesh" class="visual" pos="0.0160674 -0.0318042 0.0063483" quat="0.5 -0.5 -0.5 -0.5" mesh="gripper_finger_visual" material="gripper_finger_visual_material"/>
                    <geom type="mesh" class="collision" pos="0.0160674 -0.0318042 0.0063483" quat="0.5 -0.5 -0.5 -0.5" mesh="gripper_finger_collision" material="gripper_finger_collision_material"/>
                  </body>
                  <body name="gripper_finger_2" pos="-0.015975 -0.03985 -0.044" quat="1 3.72966e-16 6.66134e-16 -1.7549e-16">
                    <joint axis="0 0 1" name="gripper_pinion_mirror" type="slide" range="-0.0008729999999969052 0.026000000000003097"/>
                    <inertial pos="0.0160674 -0.0318042 0.0063483" mass="0.0171349" fullinertia="5.69429e-06 3.48204e-06 8.04558e-06 4.15596e-08 2.76812e-08 -5.7747e-07"/>
                    <geom type="mesh" class="visual" pos="0.0160674 -0.0318042 0.0063483" quat="0.5 -0.5 0.5 0.5" mesh="gripper_finger_2_visual" material="gripper_finger_2_visual_material"/>
                    <geom type="mesh" class="collision" pos="0.0160674 -0.0318042 0.0063483" quat="0.5 -0.5 0.5 0.5" mesh="gripper_finger_2_collision" material="gripper_finger_2_collision_material"/>
                  </body>
                </body>
              </body>
            </body>
          </body>
        </body>
      </body>
    </body>
  </worldbody>
  <asset>
    <mesh file="merged/elbow_yaw_link_visual.stl"/>
    <mesh file="merged/gripper_link_collision.stl"/>
    <mesh file="merged/wrist_gear_drive_visual.stl"/>
    <mesh file="merged/elbow_roll_link_visual.stl"/>
    <mesh file="merged/elbow_gear_drive_collision.stl"/>
    <mesh file="merged/gripper_finger_visual.stl"/>
    <mesh file="merged/wrist_pitch_link_collision.stl"/>
    <mesh file="merged/gripper_finger_collision.stl"/>
    <mesh file="merged/shoulder_pitch_link_collision.stl"/>
    <mesh file="merged/elbow_yaw_link_collision.stl"/>
    <mesh file="merged/shoulder_yaw_link_visual.stl"/>
    <mesh file="merged/shoulder_pitch_link_visual.stl"/>
    <mesh file="merged/wrist_pitch_link_visual.stl"/>
    <mesh file="merged/shoulder_roll_link_collision.stl"/>
    <mesh file="merged/gripper_link_visual.stl"/>
    <mesh file="merged/gripper_gear_drive_collision.stl"/>
    <mesh file="merged/shoulder_gear_drive_visual.stl"/>
    <mesh file="merged/shoulder_gear_drive_collision.stl"/>
    <mesh file="merged/shoulder_roll_link_visual.stl"/>
    <mesh file="merged/gripper_finger_2_collision.stl"/>
    <mesh file="merged/wrist_gear_drive_collision.stl"/>
    <mesh file="merged/gripper_finger_2_visual.stl"/>
    <mesh file="merged/elbow_gear_drive_visual.stl"/>
    <mesh file="merged/gripper_gear_drive_visual.stl"/>
    <mesh file="merged/elbow_roll_link_collision.stl"/>
    <mesh file="merged/shoulder_yaw_link_collision.stl"/>
    <material name="shoulder_pitch_link_visual_material" rgba="0.615686 0.811765 0.929412 1"/>
    <material name="shoulder_pitch_link_collision_material" rgba="0.615686 0.811765 0.929412 1"/>
    <material name="shoulder_roll_link_visual_material" rgba="0.75922 0.862174 0.917756 1"/>
    <material name="shoulder_roll_link_collision_material" rgba="0.75922 0.862174 0.917756 1"/>
    <material name="shoulder_gear_drive_visual_material" rgba="0.615686 0.811765 0.929412 1"/>
    <material name="shoulder_gear_drive_collision_material" rgba="0.615686 0.811765 0.929412 1"/>
    <material name="shoulder_yaw_link_visual_material" rgba="0.542005 0.729062 0.886557 1"/>
    <material name="shoulder_yaw_link_collision_material" rgba="0.542005 0.729062 0.886557 1"/>
    <material name="elbow_roll_link_visual_material" rgba="0.75922 0.862174 0.917756 1"/>
    <material name="elbow_roll_link_collision_material" rgba="0.75922 0.862174 0.917756 1"/>
    <material name="elbow_gear_drive_visual_material" rgba="0.615686 0.811765 0.929412 1"/>
    <material name="elbow_gear_drive_collision_material" rgba="0.615686 0.811765 0.929412 1"/>
    <material name="elbow_yaw_link_visual_material" rgba="0.516885 0.653641 0.793594 1"/>
    <material name="elbow_yaw_link_collision_material" rgba="0.516885 0.653641 0.793594 1"/>
    <material name="wrist_pitch_link_visual_material" rgba="0.748702 0.84202 0.892409 1"/>
    <material name="wrist_pitch_link_collision_material" rgba="0.748702 0.84202 0.892409 1"/>
    <material name="wrist_gear_drive_visual_material" rgba="0.615686 0.811765 0.929412 1"/>
    <material name="wrist_gear_drive_collision_material" rgba="0.615686 0.811765 0.929412 1"/>
    <material name="gripper_link_visual_material" rgba="0.63249 0.756582 0.795263 1"/>
    <material name="gripper_link_collision_material" rgba="0.63249 0.756582 0.795263 1"/>
    <material name="gripper_gear_drive_visual_material" rgba="0.647059 0.647059 0.647059 1"/>
    <material name="gripper_gear_drive_collision_material" rgba="0.647059 0.647059 0.647059 1"/>
    <material name="gripper_finger_visual_material" rgba="0.615686 0.811765 0.929412 1"/>
    <material name="gripper_finger_collision_material" rgba="0.615686 0.811765 0.929412 1"/>
    <material name="gripper_finger_2_visual_material" rgba="0.615686 0.811765 0.929412 1"/>
    <material name="gripper_finger_2_collision_material" rgba="0.615686 0.811765 0.929412 1"/>
  </asset>
  <actuator>
    <position class="left_arm_gripper" name="shoulder_roll" joint="shoulder_roll" inheritrange="1"/>
    <position class="left_arm_gripper" name="shoulder_yaw_drive" joint="shoulder_yaw_drive" inheritrange="1"/>
    <position class="left_arm_gripper" name="elbow_roll" joint="elbow_roll" inheritrange="1"/>
    <position class="left_arm_gripper" name="elbow_yaw_drive" joint="elbow_yaw_drive" inheritrange="1"/>
    <position class="left_arm_gripper" name="wrist_pitch_drive" joint="wrist_pitch_drive" inheritrange="1"/>
    <position class="left_arm_gripper" name="wrist_roll" joint="wrist_roll" inheritrange="1"/>
    <position class="left_arm_gripper" name="gripper_rack" joint="gripper_rack" inheritrange="1"/>
  </actuator>
  <equality>
    <joint joint1="shoulder_yaw_driven" joint2="shoulder_yaw_drive" polycoef="0 -1.0 0 0 0"/>
    <joint joint1="elbow_yaw_driven" joint2="elbow_yaw_drive" polycoef="0 -1.0 0 0 0"/>
    <joint joint1="wrist_pitch_driven" joint2="wrist_pitch_drive" polycoef="0 -1.0 0 0 0"/>
  </equality>
</mujoco>