<?xml version="1.0"?>
<mujoco model="teleop_leader">
  <compiler angle="radian" meshdir="assets" autolimits="true"/>
  <default class="main">
    <geom condim="1" contype="0" conaffinity="0"/>
    <joint damping="0.01" armature="0.0" frictionloss="0.01"/>
    <position inheritrange="1" forcerange="-10 10"/>
    <default class="visual">
      <geom group="2" density="0"/>
    </default>
    <default class="collision">
      <geom group="3"/>
    </default>
    <default class="XC330">
      <joint damping="0.001" armature="0.0048" frictionloss="0.006"/>
    </default>
    <default class="XC430">
      <joint damping="0.0072" armature="0.0044" frictionloss="0.014"/>
    </default>
    <default class="XM430-W350">
      <joint damping="0.0133" armature="0.0025" frictionloss="0.105"/>
    </default>
    <default class="XM430-W210">
      <joint damping="0.0064" armature="0.0022" frictionloss="0.038"/>
    </default>
    <default class="2XL430">
      <joint damping="0.0013" armature="0.0083" frictionloss="0.069"/>
    </default>
    <default class="2XC430">
      <joint damping="0.0028" armature="0.0044" frictionloss="0.06"/>
    </default>
  </default>
  <worldbody>
    <geom type="mesh" class="visual" pos="-0.0161812 0.0030935 0.0646921" quat="1.0 0.0 0.0 0.0" mesh="torso_visual"
      material="torso_visual_material"/>
    <geom type="box" class="collision" pos="-0.025508 0.0 0.06" quat="1.0 0.0 0.0 0.0" size="0.045 0.065 0.06"
      name="torso_collision_0" material="torso_visual_material"/>
    <geom type="box" class="collision" pos="-0.093008 0.0 0.01425" quat="1.0 0.0 0.0 0.0" size="0.0225 0.01425 0.01425"
      name="torso_collision_1" material="torso_visual_material"/>
    <body name="neck_yaw_gear_drive" pos="-0.0215079 0.0 0.119" quat="1 0 0 0">
      <joint axis="-0.0 0.0 -1.0" name="neck_yaw_drive" type="hinge" range="-2.8797932657906435 2.8797932657906435"
        class="XC330"/>
      <inertial pos="0.0 0.0 0.0033841" mass="0.003"
        fullinertia="8.71388e-08 8.71388e-08 1.55295e-07 -1.01369e-37 6.75285e-37 7.39046e-37"/>
      <geom type="mesh" class="visual" pos="0.0 0.0 0.0033841" quat="1.0 -0.0 0.0 0.0" mesh="neck_yaw_gear_drive_visual"
        material="neck_yaw_gear_drive_visual_material"/>
    </body>
    <body name="neck_yaw_link" pos="-0.00050787 0.0 0.124" quat="1 0 0 0">
      <joint axis="0.0 -0.0 1.0" name="neck_yaw_driven" type="hinge" range="-2.6179938779914944 2.6179938779914944"/>
      <inertial pos="-3.41e-06 -0.0 0.00821562" mass="0.006"
        fullinertia="4.77698e-07 6.2064e-07 3.29073e-07 -3.8855e-15 2.24356e-09 -2.43334e-14"/>
      <geom type="mesh" class="visual" pos="-3.41e-06 -0.0 0.00821562" quat="1.0 -0.0 0.0 0.0"
        mesh="neck_yaw_link_visual" material="neck_yaw_link_visual_material"/>
      <site group="3" name="closing_neck_pitch_front_2" pos="0.00724444 -0.004 0.0169411"
        quat="0.0 -0.0 -0.70710678 -0.70710678"/>
      <site group="3" name="closing_neck_pitch_front_2_z" pos="0.00724444 0.096 0.0169411"
        quat="0.0 -0.0 -0.70710678 -0.70710678"/>
      <site group="3" name="closing_neck_pitch_back_2" pos="-0.00724444 -0.004 0.0130589"
        quat="0.0 -0.0 -0.70710678 -0.70710678"/>
      <site group="3" name="closing_neck_pitch_back_2_z" pos="-0.00724444 0.096 0.0130589"
        quat="0.0 -0.0 -0.70710678 -0.70710678"/>
      <body name="head" pos="0.0 0.004 0.015" quat="1 0 0 0">
        <joint axis="0.0 1.0 0.0" name="neck_pitch" type="hinge" range="-0.6108652381980029 1.396263401595476"/>
        <inertial pos="-0.010438 0.00117155 0.0447912" mass="0.143321"
          fullinertia="0.00010926 0.000121889 9.62172e-05 9.18858e-07 1.09772e-05 -1.62377e-06"/>
        <geom type="mesh" class="visual" pos="-0.010438 0.00117155 0.0447912" quat="1.0 0.0 -0.0 -0.0"
          mesh="head_visual" material="head_visual_material"/>
        <geom type="box" class="collision" pos="-0.0105 -0.0035 0.046416" quat="1.0 0.0 -0.0 -0.0"
          size="0.035 0.042 0.03" name="head_collision" material="head_visual_material"/>
        <body name="neck_pitch_plate" pos="-0.027 -0.0025 0.0326157" quat="1 0 0 0">
          <joint axis="-0.0 -1.0 0.0" name="neck_pitch_act" type="hinge" range="-0.6108652381978377 1.3962634015956412"
            class="XC330"/>
          <inertial pos="-0.0 -0.00282818 0.0" mass="0.002"
            fullinertia="6.09113e-08 5.6539e-08 1.08464e-07 1.28339e-09 2.18613e-37 -3.33027e-36"/>
          <geom type="mesh" class="visual" pos="-0.0 -0.00282818 0.0" quat="1.0 -0.0 -0.0 -0.0"
            mesh="neck_pitch_plate_visual" material="neck_pitch_plate_visual_material"/>
          <body name="neck_rod" pos="0.00723736 -0.0055 0.0019674" quat="1 0 0 0">
            <joint axis="-0.0 -1.0 -0.0" name="neck_pitch_front" type="hinge"
              range="-18.488883882036536 6.643857346681808"/>
            <inertial pos="0.01348121 -0.00159086 -0.01631763" mass="0.00297389"
              fullinertia="9.56038e-07 1.72714e-08 9.68778e-07 4.62807e-10 -8.9204e-13 9.9499e-13"/>
            <geom type="mesh" class="visual" pos="0.01348121 -0.00159086 -0.01631763" quat="-1.0 -0.0 -4.6e-07 0.0"
              mesh="neck_rod_visual" material="neck_rod_visual_material"/>
            <site group="3" name="closing_neck_pitch_front_1" pos="0.02700705 0.0 -0.03264198"
              quat="0.30139095 -0.30139095 -0.63965889 -0.63965889"/>
            <site group="3" name="closing_neck_pitch_front_1_z" pos="0.02700705 0.1 -0.03264198"
              quat="0.30139095 -0.30139095 -0.63965889 -0.63965889"/>
          </body>
          <body name="neck_rod_2" pos="-0.00723736 -0.0055 -0.0019674" quat="1 0 0 0">
            <joint axis="-0.0 -1.0 0.0" name="neck_pitch_back" type="hinge"
              range="-12.206419459589366 12.926321769128979"/>
            <inertial pos="0.01348682 -0.00159086 -0.01630248" mass="0.00297389"
              fullinertia="9.55017e-07 1.72711e-08 9.67757e-07 3.79503e-10 7.32906e-13 -1.0247e-14"/>
            <geom type="mesh" class="visual" pos="0.01348682 -0.00159086 -0.01630248" quat="1.0 -0.0 2.6e-07 -0.0"
              mesh="neck_rod_2_visual" material="neck_rod_2_visual_material"/>
            <site group="3" name="closing_neck_pitch_back_1" pos="0.02699292 0.0 -0.03258941"
              quat="-0.30115987 0.30115987 0.63976772 0.63976772"/>
            <site group="3" name="closing_neck_pitch_back_1_z" pos="0.02699292 0.1 -0.03258941"
              quat="-0.30115987 0.30115987 0.63976772 0.63976772"/>
          </body>
        </body>
      </body>
    </body>
    <body name="waist_gears" pos="-0.0165079 -0.0 -0.00248651" quat="1 0 0 0">
      <joint axis="-0.0 0.0 1.0" name="waist_yaw" type="hinge" range="-1.5707963267948344 1.5707963267949587"/>
      <inertial pos="-0.0 0.0 -0.0129916" mass="0.0371617"
        fullinertia="2.6567e-06 1.19063e-05 1.15726e-05 4.54262e-13 -9.23141e-13 -1.27177e-12"/>
      <geom type="mesh" class="visual" pos="-0.0 0.0 -0.0129916" quat="1.0 0.0 0.0 0.0" mesh="waist_gears_visual"
        material="waist_gears_visual_material"/>
      <body name="pelvis_link" pos="0.0230079 -0.0 -0.014" quat="1 0 0 0">
        <joint axis="1.0 -0.0 0.0" name="waist_roll" type="hinge" range="-0.5235987755985537 0.5235987755980439"
          damping="0.5" armature="0.002" frictionloss="0.03"/>
        <inertial pos="-0.0221754 0.00026347 -0.0781825" mass="0.871763"
          fullinertia="0.00152778 0.00143144 0.0021097 3.75529e-06 9.86114e-06 6.55352e-05"/>
        <geom type="mesh" class="visual" pos="-0.0221754 0.00026347 -0.0781825" quat="1.0 0.0 -0.0 -0.0"
          mesh="pelvis_link_visual" material="pelvis_link_visual_material"/>
        <geom type="box" class="collision" pos="-0.02275 0.0 -0.035346" quat="1.0 0.0 -0.0 -0.0"
          size="0.035 0.06 0.022169" name="pelvis_link_collision" material="pelvis_link_visual_material"/>
        <body name="waist_gear_drive" pos="-0.01275 0.0 -0.0196" quat="1 0 0 0">
          <joint axis="-0.0 0.0 1.0" name="waist_act_1" type="hinge" range="-4.677482395344742 4.677482395344865"
            class="XC330"/>
          <inertial pos="0.0 -0.0 0.00671824" mass="0.002"
            fullinertia="3.70258e-08 3.70258e-08 3.95436e-08 -1.39638e-16 2.14499e-15 -3.4519e-16"/>
          <geom type="mesh" class="visual" pos="0.0 -0.0 0.00671824" quat="1.0 0.0 0.0 -0.0"
            mesh="waist_gear_drive_visual" material="waist_gear_drive_visual_material"/>
        </body>
        <body name="waist_gear_drive_2" pos="-0.03275 0.0 -0.0196" quat="1 0 0 0">
          <joint axis="-0.0 0.0 1.0" name="waist_act_2" type="hinge" range="-4.67748239534476 4.677482395344847"
            class="XC330"/>
          <inertial pos="0.0 -0.0 0.00671824" mass="0.002"
            fullinertia="3.70258e-08 3.70258e-08 3.95436e-08 -1.39638e-16 2.14499e-15 -3.4519e-16"/>
          <geom type="mesh" class="visual" pos="0.0 -0.0 0.00671824" quat="1.0 0.0 0.0 -0.0"
            mesh="waist_gear_drive_2_visual" material="waist_gear_drive_2_visual_material"/>
        </body>
      </body>
    </body>
    <body name="left_shoulder_pitch_link" pos="-0.0200079 0.067 0.10175" quat="1 0 0 0">
      <joint axis="0.0 1.0 0.0" name="left_shoulder_pitch" type="hinge" range="-4.71238898038469 4.71238898038469"
        class="XC430"/>
      <inertial pos="0.0 0.0126181 -0.00340591" mass="0.015"
        fullinertia="3.15515e-06 6.46393e-06 7.18717e-06 5.18953e-22 2.31679e-21 6.81062e-07"/>
      <geom type="mesh" class="visual" pos="0.0 0.0126181 -0.00340591" quat="1.0 0.0 0.0 0.0"
        mesh="left_shoulder_pitch_link_visual" material="shoulder_pitch_link_visual_material"/>
      <body name="left_shoulder_roll_link" pos="-0.019 0.027 -0.0107595" quat="1 0 0 0">
        <joint axis="1.0 0.0 0.0" name="left_shoulder_roll" type="hinge" range="-0.4363323129985824 1.5707963267948966"
          class="2XL430"/>
        <inertial pos="0.0185402 0.0117742 -0.00203621" mass="0.1152"
          fullinertia="2.66048e-05 3.22106e-05 3.47015e-05 -5.23536e-07 3.29512e-08 -6.36618e-07"/>
        <geom type="mesh" class="visual" pos="0.0185402 0.0117742 -0.00203621" quat="1.0 0.0 0.0 0.0"
          mesh="left_shoulder_roll_link_visual" material="shoulder_roll_link_visual_material"/>
        <geom type="box" class="collision" pos="0.01855002 0.01200003 -0.003" quat="1.0 0.0 0.0 0.0"
          size="0.02045 0.02325 0.023" name="left_shoulder_roll_link_collision"
          material="shoulder_roll_link_visual_material"/>
        <body name="left_shoulder_gear_drive" pos="0.019 0.024 -0.019" quat="1 0 0 0">
          <joint axis="0.0 0.0 1.0" name="left_shoulder_yaw_drive" type="hinge"
            range="-3.141592653589793 3.141592653589793" class="2XL430"/>
          <inertial pos="0.0 0.0 -0.00662386" mass="0.004"
            fullinertia="1.9527e-07 1.9527e-07 2.87762e-07 -2.80555e-15 -2.40741e-35 0"/>
          <geom type="mesh" class="visual" pos="0.0 0.0 -0.00662386" quat="1.0 -0.0 0.0 0.0"
            mesh="left_shoulder_gear_drive_visual" material="shoulder_gear_drive_visual_material"/>
        </body>
        <body name="left_shoulder_yaw_link" pos="0.019 0.0 -0.025" quat="1 0 0 0">
          <joint axis="0.0 0.0 -1.0" name="left_shoulder_yaw_driven" type="hinge"
            range="-3.141592653589793 3.141592653589793"/>
          <inertial pos="-0.0 0.0 -0.0282698" mass="0.0247439"
            fullinertia="9.99474e-06 1.34615e-05 5.23493e-06 -4.50573e-13 -3.13064e-22 -8.53815e-20"/>
          <geom type="mesh" class="visual" pos="-0.0 0.0 -0.0282698" quat="1.0 -0.0 0.0 0.0"
            mesh="left_shoulder_yaw_link_visual" material="shoulder_yaw_link_visual_material"/>
          <geom type="box" class="collision" pos="0.0 0.0 -0.04425" quat="1.0 -0.0 0.0 0.0"
            size="0.023 0.0129925 0.027107" name="left_shoulder_yaw_link_collision"
            material="shoulder_yaw_link_visual_material"/>
          <body name="left_elbow_roll_link" pos="-0.019 0.0 -0.061" quat="1 0 0 0">
            <joint axis="1.0 0.0 0.0" name="left_elbow_roll" type="hinge"
              range="-2.2689280275926276 8.881784197001252e-16" class="2XL430"/>
            <inertial pos="0.0185402 0.0117742 -0.00203621" mass="0.1152"
              fullinertia="2.66048e-05 3.22106e-05 3.47015e-05 -5.23536e-07 -3.29512e-08 6.36618e-07"/>
            <geom type="mesh" class="visual" pos="0.0185402 0.0117742 -0.00203621" quat="-1.0 0.0 0.0 0.0"
              mesh="left_elbow_roll_link_visual" material="elbow_roll_link_visual_material"/>
            <geom type="box" class="collision" pos="0.01855002 0.01200003 -0.003" quat="-1.0 0.0 0.0 0.0"
              size="0.02045 0.02325 0.023" name="left_elbow_roll_link_collision"
              material="elbow_roll_link_visual_material"/>
            <body name="left_elbow_gear_drive" pos="0.019 0.024 -0.019" quat="1 0 0 0">
              <joint axis="0.0 0.0 1.0" name="left_elbow_yaw_drive" type="hinge"
                range="-3.1415926535897922 3.141592653589794" class="2XL430"/>
              <inertial pos="-0.0 -0.0 -0.00662386" mass="0.004"
                fullinertia="1.9527e-07 1.9527e-07 2.87762e-07 -2.80555e-15 -1.20371e-35 1.20371e-35"/>
              <geom type="mesh" class="visual" pos="-0.0 -0.0 -0.00662386" quat="-1.0 0.0 -0.0 -0.0"
                mesh="left_elbow_gear_drive_visual" material="elbow_gear_drive_visual_material"/>
            </body>
            <body name="left_elbow_yaw_link" pos="0.019 0.0 -0.025" quat="1 0 0 0">
              <joint axis="0.0 0.0 -1.0" name="left_elbow_yaw_driven" type="hinge"
                range="-3.141592653589794 3.1415926535897922"/>
              <inertial pos="-0.0 0.00632991 -0.0336872" mass="0.0295299"
                fullinertia="2.87888e-05 1.67326e-05 1.41008e-05 2.23812e-13 9.4146e-16 3.99712e-06"/>
              <geom type="mesh" class="visual" pos="-0.0 0.00632991 -0.0336872" quat="1.0 -0.0 0.0 0.0"
                mesh="left_elbow_yaw_link_visual" material="elbow_yaw_link_visual_material"/>
              <geom type="box" class="collision" pos="0.0 0.00335 -0.04475" quat="1.0 -0.0 0.0 0.0"
                size="0.0129925 0.02965 0.027563" name="left_elbow_yaw_link_collision"
                material="elbow_yaw_link_visual_material"/>
              <body name="left_wrist_pitch_link" pos="-0.0 0.022 -0.061" quat="1 0 0 0">
                <joint axis="0.0 -1.0 0.0" name="left_wrist_pitch_driven" type="hinge"
                  range="-2.0943951023931953 2.0943951023931953"/>
                <inertial pos="-0.00041505 -0.0218673 0.011508" mass="0.1276"
                  fullinertia="3.30134e-05 4.15977e-05 3.57593e-05 1.9227e-08 -1.97148e-07 5.35788e-07"/>
                <geom type="mesh" class="visual" pos="-0.00041505 -0.0218673 0.011508" quat="-1.0 0.0 0.0 0.0"
                  mesh="left_wrist_pitch_link_visual" material="wrist_pitch_link_visual_material"/>
                <geom type="box" class="collision" pos="-0.00045 -0.02150003 0.01200003" quat="-1.0 0.0 0.0 0.0"
                  size="0.02045 0.0225 0.02325" name="left_wrist_pitch_link_collision"
                  material="wrist_pitch_link_visual_material"/>
                <body name="left_wrist_gear_drive" pos="0.0 -0.003 0.024" quat="1 0 0 0">
                  <joint axis="0.0 1.0 -0.0" name="left_wrist_pitch_drive" type="hinge"
                    range="-2.0943951023931953 2.0943951023931953" class="2XL430"/>
                  <inertial pos="0.0 0.00503438 -0.0" mass="0.003"
                    fullinertia="1.33264e-07 1.33264e-07 2.24433e-07 1.59295e-15 2.38389e-35 -1.24347e-36"/>
                  <geom type="mesh" class="visual" pos="0.0 0.00503438 -0.0" quat="-1.0 0.0 -0.0 -0.0"
                    mesh="left_wrist_gear_drive_visual" material="wrist_gear_drive_visual_material"/>
                </body>
                <body name="left_leader_hand" pos="-0.019 -0.022 -0.0" quat="1 0 0 0">
                  <joint axis="-1.0 0.0 0.0" name="left_wrist_roll" type="hinge"
                    range="-1.5707963267941443 1.5707963267956488" class="2XL430"/>
                  <inertial pos="0.0186609 2e-08 -0.0406582" mass="0.017"
                    fullinertia="9.19142e-06 6.63273e-06 3.79456e-06 1.39884e-12 -9.47511e-12 4.48222e-08"/>
                  <geom type="mesh" class="visual" pos="0.0186609 2e-08 -0.0406582" quat="1.0 0.0 0.0 0.0"
                    mesh="left_leader_hand_visual" material="leader_hand_visual_material"/>
                  <geom type="box" class="collision" pos="0.019 0.0 -0.0465" quat="1.0 0.0 0.0 0.0"
                    size="0.0315 0.0105 0.0125" name="left_leader_hand_collision" material="leader_hand_visual_material"/>
                  <site name="left_hand_center" pos="0.019 0.0 -0.059" type="sphere" size="0.005" rgba="0.9 0.1 0.1 0.8"/>
                </body>
              </body>
            </body>
          </body>
        </body>
      </body>
    </body>
    <body name="right_shoulder_pitch_link" pos="-0.0200079 -0.067 0.10175" quat="1 0 0 0">
      <joint axis="0.0 -1.0 0.0" name="right_shoulder_pitch" type="hinge" range="-4.689088611186117 4.735689349583263"
        class="XC430"/>
      <inertial pos="-0.0 -0.0126181 -0.00340591" mass="0.015"
        fullinertia="3.15515e-06 6.46393e-06 7.18717e-06 6.06171e-22 -2.1187e-21 -6.81062e-07"/>
      <geom type="mesh" class="visual" pos="-0.0 -0.0126181 -0.00340591" quat="1.0 0.0 0.0 0.0"
        mesh="right_shoulder_pitch_link_visual" material="shoulder_pitch_link_visual_material"/>
      <body name="right_shoulder_roll_link" pos="0.019 -0.027 -0.0107595" quat="1 0 0 0">
        <joint axis="-1.0 0.0 0.0" name="right_shoulder_roll" type="hinge"
          range="-0.4363323129985824 1.5707963267948966" class="2XL430"/>
        <inertial pos="-0.0185402 -0.0117742 -0.00203621" mass="0.1152"
          fullinertia="2.66048e-05 3.22106e-05 3.47015e-05 -5.23536e-07 3.29512e-08 -6.36618e-07"/>
        <geom type="mesh" class="visual" pos="-0.0185402 -0.0117742 -0.00203621" quat="1.0 0.0 0.0 0.0"
          mesh="right_shoulder_roll_link_visual" material="shoulder_roll_link_visual_material"/>
        <geom type="box" class="collision" pos="-0.01855002 -0.01200003 -0.003" quat="1.0 0.0 0.0 0.0"
          size="0.02045 0.02325 0.023" name="right_shoulder_roll_link_collision"
          material="shoulder_roll_link_visual_material"/>
        <body name="right_shoulder_gear_drive" pos="-0.019 -0.024 -0.019" quat="1 0 0 0">
          <joint axis="0.0 0.0 1.0" name="right_shoulder_yaw_drive" type="hinge"
            range="-3.141592653589793 3.141592653589793" class="2XL430"/>
          <inertial pos="-0.0 -0.0 -0.00662386" mass="0.004"
            fullinertia="1.9527e-07 1.9527e-07 2.87762e-07 -2.80555e-15 2.40741e-35 -6.01853e-36"/>
          <geom type="mesh" class="visual" pos="-0.0 -0.0 -0.00662386" quat="1.0 0.0 -0.0 0.0"
            mesh="right_shoulder_gear_drive_visual" material="shoulder_gear_drive_visual_material"/>
        </body>
        <body name="right_shoulder_yaw_link" pos="-0.019 -0.0 -0.025" quat="1 0 0 0">
          <joint axis="0.0 0.0 -1.0" name="right_shoulder_yaw_driven" type="hinge"
            range="-3.141592653589793 3.141592653589793"/>
          <inertial pos="0.0 -0.0 -0.0282698" mass="0.0247439"
            fullinertia="9.99474e-06 1.34615e-05 5.23493e-06 -4.50573e-13 3.26327e-22 -8.4756e-20"/>
          <geom type="mesh" class="visual" pos="0.0 -0.0 -0.0282698" quat="1.0 0.0 -0.0 0.0"
            mesh="right_shoulder_yaw_link_visual" material="shoulder_yaw_link_visual_material"/>
          <geom type="box" class="collision" pos="0.0 0.0 -0.04425" quat="1.0 0.0 -0.0 0.0"
            size="0.023 0.0129925 0.027107" name="right_shoulder_yaw_link_collision"
            material="shoulder_yaw_link_visual_material"/>
          <body name="right_elbow_roll_link" pos="0.019 -0.0 -0.061" quat="1 0 0 0">
            <joint axis="-1.0 0.0 0.0" name="right_elbow_roll" type="hinge"
              range="-2.268928027592625 3.552713678800501e-15" class="2XL430"/>
            <inertial pos="-0.0185402 -0.0117742 -0.00203621" mass="0.1152"
              fullinertia="2.66048e-05 3.22106e-05 3.47015e-05 -5.23536e-07 -3.29512e-08 6.36618e-07"/>
            <geom type="mesh" class="visual" pos="-0.0185402 -0.0117742 -0.00203621" quat="1.0 0.0 0.0 0.0"
              mesh="right_elbow_roll_link_visual" material="elbow_roll_link_visual_material"/>
            <geom type="box" class="collision" pos="-0.01855002 -0.01200003 -0.003" quat="1.0 0.0 0.0 0.0"
              size="0.02045 0.02325 0.023" name="right_elbow_roll_link_collision"
              material="elbow_roll_link_visual_material"/>
            <body name="right_elbow_gear_drive" pos="-0.019 -0.024 -0.019" quat="1 0 0 0">
              <joint axis="0.0 0.0 1.0" name="right_elbow_yaw_drive" type="hinge"
                range="-3.1415926535897913 3.141592653589795" class="2XL430"/>
              <inertial pos="0.0 0.0 -0.00662386" mass="0.004"
                fullinertia="1.9527e-07 1.9527e-07 2.87762e-07 -2.80555e-15 1.20371e-35 2.40741e-35"/>
              <geom type="mesh" class="visual" pos="0.0 0.0 -0.00662386" quat="1.0 0.0 -0.0 0.0"
                mesh="right_elbow_gear_drive_visual" material="elbow_gear_drive_visual_material"/>
            </body>
            <body name="right_elbow_yaw_link" pos="-0.019 -0.0 -0.025" quat="1 0 0 0">
              <joint axis="0.0 0.0 -1.0" name="right_elbow_yaw_driven" type="hinge"
                range="-3.141592653589795 3.1415926535897913"/>
              <inertial pos="0.0 -0.00632991 -0.0336872" mass="0.0295299"
                fullinertia="2.87888e-05 1.67326e-05 1.41008e-05 2.23812e-13 9.4146e-16 3.99712e-06"/>
              <geom type="mesh" class="visual" pos="0.0 -0.00632991 -0.0336872" quat="1.0 0.0 -0.0 0.0"
                mesh="right_elbow_yaw_link_visual" material="elbow_yaw_link_visual_material"/>
              <geom type="box" class="collision" pos="0.0 -0.00335 -0.04475" quat="1.0 0.0 -0.0 0.0"
                size="0.0129925 0.02965 0.027563" name="right_elbow_yaw_link_collision"
                material="elbow_yaw_link_visual_material"/>
              <body name="right_wrist_pitch_link" pos="0.0 -0.022 -0.061" quat="1 0 0 0">
                <joint axis="0.0 1.0 0.0" name="right_wrist_pitch_driven" type="hinge"
                  range="-2.0943951023931953 2.0943951023931953"/>
                <inertial pos="0.00041505 0.0218673 0.011508" mass="0.1276"
                  fullinertia="3.30134e-05 4.15977e-05 3.57593e-05 1.9227e-08 -1.97148e-07 5.35788e-07"/>
                <geom type="mesh" class="visual" pos="0.00041505 0.0218673 0.011508" quat="-1.0 0.0 0.0 0.0"
                  mesh="right_wrist_pitch_link_visual" material="wrist_pitch_link_visual_material"/>
                <geom type="box" class="collision" pos="0.00045 0.02150003 0.01200003" quat="-1.0 0.0 0.0 0.0"
                  size="0.02045 0.0225 0.02325" name="right_wrist_pitch_link_collision"
                  material="wrist_pitch_link_visual_material"/>
                <body name="right_wrist_gear_drive" pos="-0.0 0.003 0.024" quat="1 0 0 0">
                  <joint axis="-0.0 -1.0 -0.0" name="right_wrist_pitch_drive" type="hinge"
                    range="-2.0943951023931953 2.0943951023931953" class="2XL430"/>
                  <inertial pos="-0.0 -0.00503438 -0.0" mass="0.003"
                    fullinertia="1.33264e-07 1.33264e-07 2.24433e-07 1.59295e-15 1.48407e-35 7.05737e-36"/>
                  <geom type="mesh" class="visual" pos="-0.0 -0.00503438 -0.0" quat="1.0 0.0 -0.0 0.0"
                    mesh="right_wrist_gear_drive_visual" material="wrist_gear_drive_visual_material"/>
                </body>
                <body name="right_leader_hand" pos="0.019 0.022 -0.0" quat="1 0 0 0">
                  <joint axis="1.0 0.0 0.0" name="right_wrist_roll" type="hinge"
                    range="-1.5707963267941452 1.570796326795648" class="2XL430"/>
                  <inertial pos="-0.0193391 2e-08 -0.0406582" mass="0.017"
                    fullinertia="9.19142e-06 6.63273e-06 3.79456e-06 -1.39884e-12 9.47511e-12 4.48222e-08"/>
                  <geom type="mesh" class="visual" pos="-0.0193391 2e-08 -0.0406582" quat="-1.0 0.0 0.0 0.0"
                    mesh="right_leader_hand_visual" material="leader_hand_visual_material"/>
                  <geom type="box" class="collision" pos="-0.019 0.0 -0.0465" quat="-1.0 0.0 0.0 0.0"
                    size="0.0315 0.0105 0.0125" name="right_leader_hand_collision"
                    material="leader_hand_visual_material"/>
                  <site name="right_hand_center" pos="-0.019 0.0 -0.059" type="sphere" size="0.005"
                    rgba="0.9 0.1 0.1 0.8"/>
                </body>
              </body>
            </body>
          </body>
        </body>
      </body>
    </body>
    <site name="torso_center" pos="0.023 0.0 0.05" type="sphere" size="0.005" rgba="0.9 0.1 0.1 0.8"/>
  </worldbody>
  <asset>
    <mesh file="head_visual.stl"/>
    <mesh file="left_elbow_gear_drive_visual.stl"/>
    <mesh file="left_elbow_roll_link_visual.stl"/>
    <mesh file="left_elbow_yaw_link_visual.stl"/>
    <mesh file="left_leader_hand_visual.stl"/>
    <mesh file="left_shoulder_gear_drive_visual.stl"/>
    <mesh file="left_shoulder_pitch_link_visual.stl"/>
    <mesh file="left_shoulder_roll_link_visual.stl"/>
    <mesh file="left_shoulder_yaw_link_visual.stl"/>
    <mesh file="left_wrist_gear_drive_visual.stl"/>
    <mesh file="left_wrist_pitch_link_visual.stl"/>
    <mesh file="neck_pitch_plate_visual.stl"/>
    <mesh file="neck_rod_2_visual.stl"/>
    <mesh file="neck_rod_visual.stl"/>
    <mesh file="neck_yaw_gear_drive_visual.stl"/>
    <mesh file="neck_yaw_link_visual.stl"/>
    <mesh file="pelvis_link_visual.stl"/>
    <mesh file="right_elbow_gear_drive_visual.stl"/>
    <mesh file="right_elbow_roll_link_visual.stl"/>
    <mesh file="right_elbow_yaw_link_visual.stl"/>
    <mesh file="right_leader_hand_visual.stl"/>
    <mesh file="right_shoulder_gear_drive_visual.stl"/>
    <mesh file="right_shoulder_pitch_link_visual.stl"/>
    <mesh file="right_shoulder_roll_link_visual.stl"/>
    <mesh file="right_shoulder_yaw_link_visual.stl"/>
    <mesh file="right_wrist_gear_drive_visual.stl"/>
    <mesh file="right_wrist_pitch_link_visual.stl"/>
    <mesh file="torso_visual.stl"/>
    <mesh file="waist_gear_drive_2_visual.stl"/>
    <mesh file="waist_gear_drive_visual.stl"/>
    <mesh file="waist_gears_visual.stl"/>
    <material name="elbow_gear_drive_visual_material" rgba="0.615686 0.811765 0.929412 1"/>
    <material name="elbow_roll_link_visual_material" rgba="0.75922 0.862174 0.917756 1"/>
    <material name="elbow_yaw_link_visual_material" rgba="0.516885 0.653641 0.793594 1"/>
    <material name="head_visual_material" rgba="0.628184 0.794414 0.875689 1"/>
    <material name="leader_hand_visual_material" rgba="0.615686 0.811765 0.929412 1"/>
    <material name="neck_pitch_plate_visual_material" rgba="0.647059 0.647059 0.647059 1"/>
    <material name="neck_rod_2_visual_material" rgba="0.62596 0.757827 0.836947 1"/>
    <material name="neck_rod_visual_material" rgba="0.62596 0.757827 0.836947 1"/>
    <material name="neck_yaw_gear_drive_visual_material" rgba="0.647059 0.647059 0.647059 1"/>
    <material name="neck_yaw_link_visual_material" rgba="0.231373 0.380392 0.705882 1"/>
    <material name="pelvis_link_visual_material" rgba="0.621457 0.793612 0.891442 1"/>
    <material name="shoulder_gear_drive_visual_material" rgba="0.615686 0.811765 0.929412 1"/>
    <material name="shoulder_pitch_link_visual_material" rgba="0.615686 0.811765 0.929412 1"/>
    <material name="shoulder_roll_link_visual_material" rgba="0.75922 0.862174 0.917756 1"/>
    <material name="shoulder_yaw_link_visual_material" rgba="0.542005 0.729062 0.886557 1"/>
    <material name="torso_visual_material" rgba="0.56824 0.733769 0.86375 1"/>
    <material name="waist_gear_drive_2_visual_material" rgba="0.647059 0.647059 0.647059 1"/>
    <material name="waist_gear_drive_visual_material" rgba="0.647059 0.647059 0.647059 1"/>
    <material name="waist_gears_visual_material" rgba="0.307262 0.428048 0.687761 1"/>
    <material name="wrist_gear_drive_visual_material" rgba="0.615686 0.811765 0.929412 1"/>
    <material name="wrist_pitch_link_visual_material" rgba="0.748702 0.84202 0.892409 1"/>
  </asset>
  <actuator>
    <position name="neck_yaw_drive" joint="neck_yaw_drive" kp="10.0"/>
    <position name="neck_pitch_act" joint="neck_pitch_act" kp="10.0"/>
    <position name="waist_act_1" joint="waist_act_1" kp="10.0"/>
    <position name="waist_act_2" joint="waist_act_2" kp="10.0"/>
    <position name="left_shoulder_pitch" joint="left_shoulder_pitch" kp="6.0"/>
    <position name="left_shoulder_roll" joint="left_shoulder_roll" kp="6.0"/>
    <position name="left_shoulder_yaw_drive" joint="left_shoulder_yaw_drive" kp="6.0"/>
    <position name="left_elbow_roll" joint="left_elbow_roll" kp="6.0"/>
    <position name="left_elbow_yaw_drive" joint="left_elbow_yaw_drive" kp="6.0"/>
    <position name="left_wrist_pitch_drive" joint="left_wrist_pitch_drive" kp="6.0"/>
    <position name="left_wrist_roll" joint="left_wrist_roll" kp="6.0"/>
    <position name="right_shoulder_pitch" joint="right_shoulder_pitch" kp="6.0"/>
    <position name="right_shoulder_roll" joint="right_shoulder_roll" kp="6.0"/>
    <position name="right_shoulder_yaw_drive" joint="right_shoulder_yaw_drive" kp="6.0"/>
    <position name="right_elbow_roll" joint="right_elbow_roll" kp="6.0"/>
    <position name="right_elbow_yaw_drive" joint="right_elbow_yaw_drive" kp="6.0"/>
    <position name="right_wrist_pitch_drive" joint="right_wrist_pitch_drive" kp="6.0"/>
    <position name="right_wrist_roll" joint="right_wrist_roll" kp="6.0"/>
  </actuator>
  <equality>
    <connect site1="closing_neck_pitch_front_1" site2="closing_neck_pitch_front_2" solref="0.004 1"
      solimp="0.9999 0.9999 0.001 0.5 2"/>
    <connect site1="closing_neck_pitch_front_1_z" site2="closing_neck_pitch_front_2_z" solref="0.004 1"
      solimp="0.9999 0.9999 0.001 0.5 2"/>
    <connect site1="closing_neck_pitch_back_1" site2="closing_neck_pitch_back_2" solref="0.004 1"
      solimp="0.9999 0.9999 0.001 0.5 2"/>
    <connect site1="closing_neck_pitch_back_1_z" site2="closing_neck_pitch_back_2_z" solref="0.004 1"
      solimp="0.9999 0.9999 0.001 0.5 2"/>
    <joint joint1="neck_yaw_driven" joint2="neck_yaw_drive" polycoef="0 -0.9090909091 0 0 0"/>
    <joint joint1="left_shoulder_yaw_driven" joint2="left_shoulder_yaw_drive" polycoef="0 -1.0 0 0 0"/>
    <joint joint1="left_elbow_yaw_driven" joint2="left_elbow_yaw_drive" polycoef="0 -1.0 0 0 0"/>
    <joint joint1="left_wrist_pitch_driven" joint2="left_wrist_pitch_drive" polycoef="0 -1.0 0 0 0"/>
    <joint joint1="right_shoulder_yaw_driven" joint2="right_shoulder_yaw_drive" polycoef="0 -1.0 0 0 0"/>
    <joint joint1="right_elbow_yaw_driven" joint2="right_elbow_yaw_drive" polycoef="0 -1.0 0 0 0"/>
    <joint joint1="right_wrist_pitch_driven" joint2="right_wrist_pitch_drive" polycoef="0 -1.0 0 0 0"/>
  </equality>
  <sensor>
    <framelinvel objtype="site" objname="torso_center" name="torso_center_linvel"/>
    <frameangvel objtype="site" objname="torso_center" name="torso_center_angvel"/>
    <framelinvel objtype="site" objname="left_hand_center" name="left_hand_center_linvel"/>
    <frameangvel objtype="site" objname="left_hand_center" name="left_hand_center_angvel"/>
    <framelinvel objtype="site" objname="right_hand_center" name="right_hand_center_linvel"/>
    <frameangvel objtype="site" objname="right_hand_center" name="right_hand_center_angvel"/>
  </sensor>
  <contact>
    <pair geom1="torso_collision_0" geom2="left_shoulder_yaw_link_collision"/>
    <pair geom1="torso_collision_0" geom2="left_elbow_roll_link_collision"/>
    <pair geom1="torso_collision_0" geom2="left_elbow_yaw_link_collision"/>
    <pair geom1="torso_collision_0" geom2="left_wrist_pitch_link_collision"/>
    <pair geom1="torso_collision_0" geom2="left_leader_hand_collision"/>
    <pair geom1="torso_collision_0" geom2="right_shoulder_yaw_link_collision"/>
    <pair geom1="torso_collision_0" geom2="right_elbow_roll_link_collision"/>
    <pair geom1="torso_collision_0" geom2="right_elbow_yaw_link_collision"/>
    <pair geom1="torso_collision_0" geom2="right_wrist_pitch_link_collision"/>
    <pair geom1="torso_collision_0" geom2="right_leader_hand_collision"/>
    <pair geom1="torso_collision_1" geom2="left_elbow_yaw_link_collision"/>
    <pair geom1="torso_collision_1" geom2="left_wrist_pitch_link_collision"/>
    <pair geom1="torso_collision_1" geom2="left_leader_hand_collision"/>
    <pair geom1="torso_collision_1" geom2="right_elbow_yaw_link_collision"/>
    <pair geom1="torso_collision_1" geom2="right_wrist_pitch_link_collision"/>
    <pair geom1="torso_collision_1" geom2="right_leader_hand_collision"/>
    <pair geom1="head_collision" geom2="left_shoulder_yaw_link_collision"/>
    <pair geom1="head_collision" geom2="left_elbow_roll_link_collision"/>
    <pair geom1="head_collision" geom2="left_elbow_yaw_link_collision"/>
    <pair geom1="head_collision" geom2="left_wrist_pitch_link_collision"/>
    <pair geom1="head_collision" geom2="left_leader_hand_collision"/>
    <pair geom1="head_collision" geom2="right_shoulder_yaw_link_collision"/>
    <pair geom1="head_collision" geom2="right_elbow_roll_link_collision"/>
    <pair geom1="head_collision" geom2="right_elbow_yaw_link_collision"/>
    <pair geom1="head_collision" geom2="right_wrist_pitch_link_collision"/>
    <pair geom1="head_collision" geom2="right_leader_hand_collision"/>
    <pair geom1="pelvis_link_collision" geom2="left_elbow_yaw_link_collision"/>
    <pair geom1="pelvis_link_collision" geom2="left_wrist_pitch_link_collision"/>
    <pair geom1="pelvis_link_collision" geom2="left_leader_hand_collision"/>
    <pair geom1="pelvis_link_collision" geom2="right_elbow_yaw_link_collision"/>
    <pair geom1="pelvis_link_collision" geom2="right_wrist_pitch_link_collision"/>
    <pair geom1="pelvis_link_collision" geom2="right_leader_hand_collision"/>
    <pair geom1="left_elbow_yaw_link_collision" geom2="right_elbow_yaw_link_collision"/>
    <pair geom1="left_elbow_yaw_link_collision" geom2="right_wrist_pitch_link_collision"/>
    <pair geom1="left_wrist_pitch_link_collision" geom2="right_elbow_yaw_link_collision"/>
    <pair geom1="left_wrist_pitch_link_collision" geom2="right_wrist_pitch_link_collision"/>
  </contact>
  <keyframe>
    <key name="home"
      qpos="0.0 -0.0 0.0 0.0 0.0 0.0 0.0 0.0 0.0 0.0 0.174533 0.087266 1.570796 -1.570796 -0.523599 -1.570796 1.570796 1.22173 -1.22173 0.0 -0.174533 0.087266 -1.570796 1.570796 -0.523599 1.570796 -1.570796 -1.22173 1.22173 0.0"
      ctrl="0 0 0 0 0.174533 0.087266 1.570796 -0.523599 -1.570796 -1.22173 0 -0.174533 0.087266 -1.570796 -0.523599 1.570796 1.22173 0"/>
  </keyframe>
</mujoco>