<?xml version="1.0" ?>
<mujoco model="right_arm_gripper">
  <compiler angle="radian" meshdir="assets" autolimits="true"/>
  <default>
    <default class="right_arm_gripper">
      <joint frictionloss="0.1" armature="0.005"/>
      <position kp="50" dampratio="1"/>
      <default class="visual">
        <geom type="mesh" contype="0" conaffinity="0" group="2"/>
      </default>
      <default class="collision">
        <geom group="3"/>
      </default>
    </default>
  </default>
  <worldbody>
    <body name="shoulder_pitch_link" pos="0 0 0" quat="1 0 0 0" childclass="right_arm_gripper">
      <freejoint name="shoulder_pitch_link_freejoint"/>
      <inertial pos="6.40684e-19 -0.0126181 -0.00340591" mass="0.015" fullinertia="3.15515e-06 6.46393e-06 7.18717e-06 -1.56918e-22 -1.71031e-21 -6.81062e-07"/>
      <geom type="mesh" class="visual" pos="6.40684e-19 -0.0126181 -0.00340591" quat="1 0 0 0" mesh="shoulder_pitch_link_visual" material="shoulder_pitch_link_visual_material"/>
      <geom type="mesh" class="collision" pos="6.40684e-19 -0.0126181 -0.00340591" quat="1 0 0 0" mesh="shoulder_pitch_link_collision" material="shoulder_pitch_link_collision_material"/>
      <body name="shoulder_roll_link" pos="0.019 -0.027 -0.0107595" quat="0.5 -0.5 -0.5 0.5">
        <joint axis="0 0 1" name="shoulder_roll" type="hinge" range="-0.4363323129985824 1.5707963267948966"/>
        <inertial pos="-0.0117742 0.00203621 0.0185402" mass="0.1152" fullinertia="2.66048e-05 3.22106e-05 3.47015e-05 -5.23536e-07 3.29512e-08 -6.36618e-07"/>
        <geom type="mesh" class="visual" pos="-0.0117742 0.00203621 0.0185402" quat="0.5 0.5 0.5 -0.5" mesh="shoulder_roll_link_visual" material="shoulder_roll_link_visual_material"/>
        <geom type="mesh" class="collision" pos="-0.0117742 0.00203621 0.0185402" quat="0.5 0.5 0.5 -0.5" mesh="shoulder_roll_link_collision" material="shoulder_roll_link_collision_material"/>
        <body name="shoulder_gear_drive" pos="-0.024 0.019 0.019" quat="0.5 0.5 -0.5 0.5">
          <joint axis="0 0 1" name="shoulder_yaw_drive" type="hinge" range="-3.141592653589793 3.141592653589793"/>
          <inertial pos="2.34903e-15 1.16135e-15 -0.00662386" mass="0.004" fullinertia="1.9527e-07 1.9527e-07 2.87762e-07 -2.80555e-15 0 0"/>
          <geom type="mesh" class="visual" pos="2.34903e-15 1.16573e-15 -0.00662386" quat="4.6143e-14 -3.485e-13 -7.10543e-14 -1" mesh="shoulder_gear_drive_visual" material="shoulder_gear_drive_visual_material"/>
          <geom type="mesh" class="collision" pos="2.34903e-15 1.16573e-15 -0.00662386" quat="4.6143e-14 -3.485e-13 -7.10543e-14 -1" mesh="shoulder_gear_drive_collision" material="shoulder_gear_drive_collision_material"/>
        </body>
        <body name="shoulder_yaw_link" pos="-3.58104e-10 0.025 0.019" quat="0.5 -0.5 -0.5 -0.5">
          <joint axis="0 0 1" name="shoulder_yaw_driven" type="hinge" range="-3.141592653589793 3.141592653589793"/>
          <inertial pos="-3.13442e-18 -1.46426e-16 0.0282698" mass="0.0247439" fullinertia="9.99474e-06 1.34615e-05 5.23493e-06 -4.50573e-13 6.74199e-23 -8.37085e-20"/>
          <geom type="mesh" class="visual" pos="-3.15594e-18 -1.45717e-16 0.0282698" quat="2.0722e-13 2.78754e-14 1 -3.70159e-13" mesh="shoulder_yaw_link_visual" material="shoulder_yaw_link_visual_material"/>
          <geom type="mesh" class="collision" pos="-3.15594e-18 -1.45717e-16 0.0282698" quat="2.0722e-13 2.78754e-14 1 -3.70159e-13" mesh="shoulder_yaw_link_collision" material="shoulder_yaw_link_collision_material"/>
          <body name="elbow_roll_link" pos="-0.019 -1.04083e-17 0.061" quat="0.5 -0.5 0.5 -0.5">
            <joint axis="0 0 1" name="elbow_roll" type="hinge" range="-2.2689280275926285 0.0"/>
            <inertial pos="0.0117742 -0.00203621 0.0185402" mass="0.1152" fullinertia="2.66048e-05 3.22106e-05 3.47015e-05 -5.23536e-07 -3.29512e-08 6.36618e-07"/>
            <geom type="mesh" class="visual" pos="0.0117742 -0.00203621 0.0185402" quat="0.5 -0.5 0.5 0.5" mesh="elbow_roll_link_visual" material="elbow_roll_link_visual_material"/>
            <geom type="mesh" class="collision" pos="0.0117742 -0.00203621 0.0185402" quat="0.5 -0.5 0.5 0.5" mesh="elbow_roll_link_collision" material="elbow_roll_link_collision_material"/>
            <body name="elbow_gear_drive" pos="0.024 -0.019 0.019" quat="0.5 -0.5 0.5 0.5">
              <joint axis="0 0 1" name="elbow_yaw_drive" type="hinge" range="-3.141592653589793 3.141592653589793"/>
              <inertial pos="2.34908e-15 1.16241e-15 -0.00662386" mass="0.004" fullinertia="1.9527e-07 1.9527e-07 2.87762e-07 -2.80555e-15 0 -3.61112e-35"/>
              <geom type="mesh" class="visual" pos="2.34908e-15 1.16573e-15 -0.00662386" quat="1 2.43125e-13 -2.24709e-13 7.70351e-14" mesh="elbow_gear_drive_visual" material="elbow_gear_drive_visual_material"/>
              <geom type="mesh" class="collision" pos="2.34908e-15 1.16573e-15 -0.00662386" quat="1 2.43125e-13 -2.24709e-13 7.70351e-14" mesh="elbow_gear_drive_collision" material="elbow_gear_drive_collision_material"/>
            </body>
            <body name="elbow_yaw_link" pos="3.58093e-10 -0.025 0.019" quat="0.5 0.5 -0.5 0.5">
              <joint axis="0 0 1" name="elbow_yaw_driven" type="hinge" range="-3.141592653589793 3.141592653589793"/>
              <inertial pos="-1.48734e-11 -0.00632991 0.0336872" mass="0.0295299" fullinertia="2.87888e-05 1.67326e-05 1.41008e-05 2.23812e-13 9.41459e-16 3.99712e-06"/>
              <geom type="mesh" class="visual" pos="-1.48734e-11 -0.00632991 0.0336872" quat="5.421e-14 2.79865e-14 1 -4.40761e-13" mesh="elbow_yaw_link_visual" material="elbow_yaw_link_visual_material"/>
              <geom type="mesh" class="collision" pos="-1.48734e-11 -0.00632991 0.0336872" quat="5.421e-14 2.79865e-14 1 -4.40761e-13" mesh="elbow_yaw_link_collision" material="elbow_yaw_link_collision_material"/>
              <body name="wrist_pitch_link" pos="-4.01846e-18 -0.022 0.061" quat="0.5 -0.5 -0.5 -0.5">
                <joint axis="0 0 1" name="wrist_pitch_driven" type="hinge" range="-2.0943951023931953 2.0943951023931953"/>
                <inertial pos="-0.011508 -0.000415054 0.0218673" mass="0.1276" fullinertia="3.30134e-05 4.15977e-05 3.57593e-05 1.9227e-08 -1.97148e-07 5.35788e-07"/>
                <geom type="mesh" class="visual" pos="-0.011508 -0.000415054 0.0218673" quat="0.5 0.5 -0.5 -0.5" mesh="wrist_pitch_link_visual" material="wrist_pitch_link_visual_material"/>
                <geom type="mesh" class="collision" pos="-0.011508 -0.000415054 0.0218673" quat="0.5 0.5 -0.5 -0.5" mesh="wrist_pitch_link_collision" material="wrist_pitch_link_collision_material"/>
                <body name="wrist_gear_drive" pos="-0.024 1.52468e-10 0.003" quat="4.94106e-13 -0.707107 0.707107 3.78567e-14">
                  <joint axis="0 0 1" name="wrist_pitch_drive" type="hinge" range="-2.0943951023931953 2.0943951023931953"/>
                  <inertial pos="2.93819e-15 -1.26918e-16 0.00503438" mass="0.003" fullinertia="1.33264e-07 1.33264e-07 2.24433e-07 1.59295e-15 1.39039e-35 -6.23408e-37"/>
                  <geom type="mesh" class="visual" pos="2.93819e-15 -1.11022e-16 0.00503438" quat="0.707107 -0.707107 9.53682e-14 4.7603e-13" mesh="wrist_gear_drive_visual" material="wrist_gear_drive_visual_material"/>
                  <geom type="mesh" class="collision" pos="2.93819e-15 -1.11022e-16 0.00503438" quat="0.707107 -0.707107 9.53682e-14 4.7603e-13" mesh="wrist_gear_drive_collision" material="wrist_gear_drive_collision_material"/>
                </body>
                <body name="gripper_link" pos="3.58074e-10 -0.019 0.022" quat="0.5 0.5 0.5 -0.5">
                  <joint axis="0 0 1" name="wrist_roll" type="hinge" range="-1.5707963267941363 1.5707963267956568"/>
                  <inertial pos="0.00424694 0.0293532 -0.039318" mass="0.0607365" fullinertia="3.08108e-05 3.1195e-05 1.57096e-05 1.09192e-06 3.17842e-06 -3.17184e-06"/>
                  <geom type="mesh" class="visual" pos="0.00424694 0.0293532 -0.039318" quat="0.5 0.5 -0.5 0.5" mesh="gripper_link_visual" material="gripper_link_visual_material"/>
                  <geom type="mesh" class="collision" pos="0.00424694 0.0293532 -0.039318" quat="0.5 0.5 -0.5 0.5" mesh="gripper_link_collision" material="gripper_link_collision_material"/>
                  <body name="gripper_gear_drive" pos="0.0001 0.0397 -0.04995" quat="0.5 0.5 -0.5 0.5">
                    <joint axis="0 0 1" name="gripper_rack" type="hinge" range="0.0 2.1642082724729685"/>
                    <inertial pos="-3.1225e-17 3.37849e-17 -0.0025" mass="0.00107037" fullinertia="2.73249e-08 2.73249e-08 5.01899e-08 4.5613e-37 1.84359e-36 9.93822e-37"/>
                    <geom type="mesh" class="visual" pos="-3.1225e-17 3.46945e-17 -0.0025" quat="1 4.18693e-14 -1.16795e-13 6.31993e-14" mesh="gripper_gear_drive_visual" material="gripper_gear_drive_visual_material"/>
                    <geom type="mesh" class="collision" pos="-3.1225e-17 3.46945e-17 -0.0025" quat="1 4.18693e-14 -1.16795e-13 6.31993e-14" mesh="gripper_gear_drive_collision" material="gripper_gear_drive_collision_material"/>
                  </body>
                  <body name="gripper_finger" pos="0.015975 0.03985 -0.064" quat="2.77556e-16 -1.37153e-16 -0 -1">
                    <joint axis="0 0 1" name="gripper_pinion" type="slide" range="-0.0008730000000033168 0.025999999999996685"/>
                    <inertial pos="0.0160674 -0.0318042 0.0063483" mass="0.0171349" fullinertia="5.69429e-06 3.48204e-06 8.04558e-06 4.15596e-08 2.76812e-08 -5.7747e-07"/>
                    <geom type="mesh" class="visual" pos="0.0160674 -0.0318042 0.0063483" quat="0.5 -0.5 -0.5 -0.5" mesh="gripper_finger_visual" material="gripper_finger_visual_material"/>
                    <geom type="mesh" class="collision" pos="0.0160674 -0.0318042 0.0063483" quat="0.5 -0.5 -0.5 -0.5" mesh="gripper_finger_collision" material="gripper_finger_collision_material"/>
                  </body>
                  <body name="gripper_finger_2" pos="-0.015975 0.03985 0.006" quat="2.25789e-16 1 1.38778e-17 -8.26059e-17">
                    <joint axis="0 0 1" name="gripper_pinion_mirror" type="slide" range="-0.0008730000000043715 0.02599999999999563"/>
                    <inertial pos="0.0160674 -0.0318042 0.0063483" mass="0.0171349" fullinertia="5.69429e-06 3.48204e-06 8.04558e-06 4.15596e-08 2.76812e-08 -5.7747e-07"/>
                    <geom type="mesh" class="visual" pos="0.0160674 -0.0318042 0.0063483" quat="0.5 -0.5 0.5 0.5" mesh="gripper_finger_2_visual" material="gripper_finger_2_visual_material"/>
                    <geom type="mesh" class="collision" pos="0.0160674 -0.0318042 0.0063483" quat="0.5 -0.5 0.5 0.5" mesh="gripper_finger_2_collision" material="gripper_finger_2_collision_material"/>
                  </body>
                </body>
              </body>
            </body>
          </body>
        </body>
      </body>
    </body>
  </worldbody>
  <asset>
    <mesh file="merged/gripper_gear_drive_visual.stl"/>
    <mesh file="merged/shoulder_roll_link_collision.stl"/>
    <mesh file="merged/gripper_finger_visual.stl"/>
    <mesh file="merged/elbow_gear_drive_collision.stl"/>
    <mesh file="merged/shoulder_gear_drive_collision.stl"/>
    <mesh file="merged/elbow_yaw_link_collision.stl"/>
    <mesh file="merged/wrist_gear_drive_visual.stl"/>
    <mesh file="merged/gripper_finger_2_collision.stl"/>
    <mesh file="merged/shoulder_pitch_link_visual.stl"/>
    <mesh file="merged/gripper_gear_drive_collision.stl"/>
    <mesh file="merged/gripper_link_collision.stl"/>
    <mesh file="merged/elbow_roll_link_collision.stl"/>
    <mesh file="merged/shoulder_yaw_link_collision.stl"/>
    <mesh file="merged/elbow_gear_drive_visual.stl"/>
    <mesh file="merged/wrist_pitch_link_visual.stl"/>
    <mesh file="merged/elbow_yaw_link_visual.stl"/>
    <mesh file="merged/elbow_roll_link_visual.stl"/>
    <mesh file="merged/shoulder_yaw_link_visual.stl"/>
    <mesh file="merged/shoulder_pitch_link_collision.stl"/>
    <mesh file="merged/shoulder_roll_link_visual.stl"/>
    <mesh file="merged/shoulder_gear_drive_visual.stl"/>
    <mesh file="merged/wrist_pitch_link_collision.stl"/>
    <mesh file="merged/wrist_gear_drive_collision.stl"/>
    <mesh file="merged/gripper_link_visual.stl"/>
    <mesh file="merged/gripper_finger_collision.stl"/>
    <mesh file="merged/gripper_finger_2_visual.stl"/>
    <material name="shoulder_pitch_link_visual_material" rgba="0.615686 0.811765 0.929412 1"/>
    <material name="shoulder_pitch_link_collision_material" rgba="0.615686 0.811765 0.929412 1"/>
    <material name="shoulder_roll_link_visual_material" rgba="0.75922 0.862174 0.917756 1"/>
    <material name="shoulder_roll_link_collision_material" rgba="0.75922 0.862174 0.917756 1"/>
    <material name="shoulder_gear_drive_visual_material" rgba="0.615686 0.811765 0.929412 1"/>
    <material name="shoulder_gear_drive_collision_material" rgba="0.615686 0.811765 0.929412 1"/>
    <material name="shoulder_yaw_link_visual_material" rgba="0.542005 0.729062 0.886557 1"/>
    <material name="shoulder_yaw_link_collision_material" rgba="0.542005 0.729062 0.886557 1"/>
    <material name="elbow_roll_link_visual_material" rgba="0.75922 0.862174 0.917756 1"/>
    <material name="elbow_roll_link_collision_material" rgba="0.75922 0.862174 0.917756 1"/>
    <material name="elbow_gear_drive_visual_material" rgba="0.615686 0.811765 0.929412 1"/>
    <material name="elbow_gear_drive_collision_material" rgba="0.615686 0.811765 0.929412 1"/>
    <material name="elbow_yaw_link_visual_material" rgba="0.516885 0.653641 0.793594 1"/>
    <material name="elbow_yaw_link_collision_material" rgba="0.516885 0.653641 0.793594 1"/>
    <material name="wrist_pitch_link_visual_material" rgba="0.748702 0.84202 0.892409 1"/>
    <material name="wrist_pitch_link_collision_material" rgba="0.748702 0.84202 0.892409 1"/>
    <material name="wrist_gear_drive_visual_material" rgba="0.615686 0.811765 0.929412 1"/>
    <material name="wrist_gear_drive_collision_material" rgba="0.615686 0.811765 0.929412 1"/>
    <material name="gripper_link_visual_material" rgba="0.63249 0.756582 0.795263 1"/>
    <material name="gripper_link_collision_material" rgba="0.63249 0.756582 0.795263 1"/>
    <material name="gripper_gear_drive_visual_material" rgba="0.647059 0.647059 0.647059 1"/>
    <material name="gripper_gear_drive_collision_material" rgba="0.647059 0.647059 0.647059 1"/>
    <material name="gripper_finger_visual_material" rgba="0.615686 0.811765 0.929412 1"/>
    <material name="gripper_finger_collision_material" rgba="0.615686 0.811765 0.929412 1"/>
    <material name="gripper_finger_2_visual_material" rgba="0.615686 0.811765 0.929412 1"/>
    <material name="gripper_finger_2_collision_material" rgba="0.615686 0.811765 0.929412 1"/>
  </asset>
  <actuator>
    <position class="right_arm_gripper" name="shoulder_roll" joint="shoulder_roll" inheritrange="1"/>
    <position class="right_arm_gripper" name="shoulder_yaw_drive" joint="shoulder_yaw_drive" inheritrange="1"/>
    <position class="right_arm_gripper" name="elbow_roll" joint="elbow_roll" inheritrange="1"/>
    <position class="right_arm_gripper" name="elbow_yaw_drive" joint="elbow_yaw_drive" inheritrange="1"/>
    <position class="right_arm_gripper" name="wrist_pitch_drive" joint="wrist_pitch_drive" inheritrange="1"/>
    <position class="right_arm_gripper" name="wrist_roll" joint="wrist_roll" inheritrange="1"/>
    <position class="right_arm_gripper" name="gripper_rack" joint="gripper_rack" inheritrange="1"/>
  </actuator>
  <equality>
    <joint joint1="shoulder_yaw_driven" joint2="shoulder_yaw_drive" polycoef="0 -1.0 0 0 0"/>
    <joint joint1="elbow_yaw_driven" joint2="elbow_yaw_drive" polycoef="0 -1.0 0 0 0"/>
    <joint joint1="wrist_pitch_driven" joint2="wrist_pitch_drive" polycoef="0 -1.0 0 0 0"/>
  </equality>
</mujoco>